Workbook

Sheet Summary – Option 1
A1: SurTrac co-packaging – priority companies and drugs (Option 1 – injectable shipments)
A2: 2x2: unit price (x) × injectable shipments (#) (y); bubble = injectable export value ($'000). Priority 1 = high price AND high volume (top-right); Priority 2 = one of the two high; Priority 3 = both lower; cut-offs = median of eligible pairs (Scoring C3 / E3). Drugs with an ID / IM / SC route on a label in the 7 geographies only (IV-only drugs removed). Companies ranked by number of Priority 1 drugs, then opportunity of Priority 1 + 2; within a company, drugs by tier, then opportunity. Price ≤ $5 listed last as Excluded.
A3: Packaging: strength and fill per unit container (no carton sizes). Avg price: average per unit (per dose for multi-dose vaccine vials) of presentations priced > $5; Excluded rows: average of all priced presentations (all ≤ $5). Volume = India FY24 shipments of the molecule (all dosage forms) × injectable share of registered products in the 7 geographies. Volume is molecule-level (same for every company). Markets: countries where the company (or its group entity) holds an authorisation – a proxy for where it is supplied. Filters, assumptions and limitations: see the tab of that name. Live – linked to Scoring; grey helper column O orders the list.
A4: Company rank | B4: Company | C4: Drug rank | D4: Priority tier | E4: 2x2 quadrant | F4: Drug (API) | G4: Product name | H4: Drug utility | I4: Presentation | J4: Packaging (per unit) | K4: Avg price (USD / unit) | L4: Injectable shipments (#) | M4: Injectable export value ($'000) | N4: Markets where the company holds an authorisation | O4: Helper: sort key
A5: =IF($O5="","",INT($O5/1000)) -> 1 | B5: =IF($O5="","",INDEX(Scoring!$A$29:$A$361,MATCH($O5,Scoring!$AB$29:$AB$361,0))) -> Intas | C5: =IF($O5="","",IF(INDEX(Scoring!$P$29:$P$361,MATCH($O5,Scoring!$AB$29:$AB$361,0))="","–",INDEX(Scoring!$P$29:$P$361,MATCH($O5,Scoring!$AB$29:$AB$361,0)))) -> 1 | D5: =IF($O5="","",INDEX(Scoring!$Q$29:$Q$361,MATCH($O5,Scoring!$AB$29:$AB$361,0))) -> Priority 1 | E5: =IF($O5="","",INDEX(Scoring!$AJ$29:$AJ$361,MATCH($O5,Scoring!$AB$29:$AB$361,0))) -> High price · high volume | F5: =IF($O5="","",INDEX(Scoring!$B$29:$B$361,MATCH($O5,Scoring!$AB$29:$AB$361,0))) -> Azacitidine | G5: =IF($O5="","",INDEX(Scoring!$AG$29:$AG$361,MATCH($O5,Scoring!$AB$29:$AB$361,0))) -> Azacitidine Accord; Azaccord | H5: =IF($O5="","",INDEX(Scoring!$C$29:$C$361,MATCH($O5,Scoring!$AB$29:$AB$361,0))) -> Oncology: myelodysplastic syndromes, acute myeloid leukaemia | I5: =IF($O5="","",INDEX(Scoring!$I$29:$I$361,MATCH($O5,Scoring!$AB$29:$AB$361,0))) -> Vial | J5: =IF($O5="","",INDEX(Scoring!$Z$29:$Z$361,MATCH($O5,Scoring!$AB$29:$AB$361,0))) -> 25 mg/mL vial; 100 mg powder vial | K5: =IF($O5="","",IF(INDEX(Scoring!$D$29:$D$361,MATCH($O5,Scoring!$AB$29:$AB$361,0))="",INDEX(Scoring!$AF$29:$AF$361,MATCH($O5,Scoring!$AB$29:$AB$361,0)),INDEX(Scoring!$D$29:$D$361,MATCH($O5,Scoring!$AB$29:$AB$361,0)))) -> 256.12 | L5: =IF($O5="","",INDEX(Scoring!$M$29:$M$361,MATCH($O5,Scoring!$AB$29:$AB$361,0))) -> 632 | M5: =IF($O5="","",INDEX(Scoring!$F$29:$F$361,MATCH($O5,Scoring!$AB$29:$AB$361,0))) -> 42181.7 | N5: =IF($O5="","",INDEX(Scoring!$AI$29:$AI$361,MATCH($O5,Scoring!$AB$29:$AB$361,0))) -> UK, Australia | EU/EEA: all 30 countries | O5: =IFERROR(SMALL(Scoring!$AB$29:$AB$361,1),"") -> 1001
A6: =IF($O6="","",INT($O6/1000)) -> 1 | B6: =IF($O6="","",INDEX(Scoring!$A$29:$A$361,MATCH($O6,Scoring!$AB$29:$AB$361,0))) -> Intas | C6: =IF($O6="","",IF(INDEX(Scoring!$P$29:$P$361,MATCH($O6,Scoring!$AB$29:$AB$361,0))="","–",INDEX(Scoring!$P$29:$P$361,MATCH($O6,Scoring!$AB$29:$AB$361,0)))) -> 2 | D6: =IF($O6="","",INDEX(Scoring!$Q$29:$Q$361,MATCH($O6,Scoring!$AB$29:$AB$361,0))) -> Priority 1 | E6: =IF($O6="","",INDEX(Scoring!$AJ$29:$AJ$361,MATCH($O6,Scoring!$AB$29:$AB$361,0))) -> High price · high volume | F6: =IF($O6="","",INDEX(Scoring!$B$29:$B$361,MATCH($O6,Scoring!$AB$29:$AB$361,0))) -> Bortezomib | G6: =IF($O6="","",INDEX(Scoring!$AG$29:$AG$361,MATCH($O6,Scoring!$AB$29:$AB$361,0))) -> Bortezomib; Bortezomib Accord; Bortezomib Intas (+1 more) | H6: =IF($O6="","",INDEX(Scoring!$C$29:$C$361,MATCH($O6,Scoring!$AB$29:$AB$361,0))) -> Oncology: multiple myeloma, mantle cell lymphoma | I6: =IF($O6="","",INDEX(Scoring!$I$29:$I$361,MATCH($O6,Scoring!$AB$29:$AB$361,0))) -> Vial, Prefilled syringe | J6: =IF($O6="","",INDEX(Scoring!$Z$29:$Z$361,MATCH($O6,Scoring!$AB$29:$AB$361,0))) -> 2 mg pre-filled syringe; 3.5 mg/1.4 mL vial; 2.5 mg/1 mL vial; 1 mg powder vial (+2 more) | K6: =IF($O6="","",IF(INDEX(Scoring!$D$29:$D$361,MATCH($O6,Scoring!$AB$29:$AB$361,0))="",INDEX(Scoring!$AF$29:$AF$361,MATCH($O6,Scoring!$AB$29:$AB$361,0)),INDEX(Scoring!$D$29:$D$361,MATCH($O6,Scoring!$AB$29:$AB$361,0)))) -> 569.27 | L6: =IF($O6="","",INDEX(Scoring!$M$29:$M$361,MATCH($O6,Scoring!$AB$29:$AB$361,0))) -> 905 | M6: =IF($O6="","",INDEX(Scoring!$F$29:$F$361,MATCH($O6,Scoring!$AB$29:$AB$361,0))) -> 28093.4 | N6: =IF($O6="","",INDEX(Scoring!$AI$29:$AI$361,MATCH($O6,Scoring!$AB$29:$AB$361,0))) -> UK, Australia, South Africa, UK-NI | EU/EEA: all 30 countries | O6: =IFERROR(SMALL(Scoring!$AB$29:$AB$361,2),"") -> 1002
A7: =IF($O7="","",INT($O7/1000)) -> 1 | B7: =IF($O7="","",INDEX(Scoring!$A$29:$A$361,MATCH($O7,Scoring!$AB$29:$AB$361,0))) -> Intas | C7: =IF($O7="","",IF(INDEX(Scoring!$P$29:$P$361,MATCH($O7,Scoring!$AB$29:$AB$361,0))="","–",INDEX(Scoring!$P$29:$P$361,MATCH($O7,Scoring!$AB$29:$AB$361,0)))) -> 3 | D7: =IF($O7="","",INDEX(Scoring!$Q$29:$Q$361,MATCH($O7,Scoring!$AB$29:$AB$361,0))) -> Priority 1 | E7: =IF($O7="","",INDEX(Scoring!$AJ$29:$AJ$361,MATCH($O7,Scoring!$AB$29:$AB$361,0))) -> High price · high volume | F7: =IF($O7="","",INDEX(Scoring!$B$29:$B$361,MATCH($O7,Scoring!$AB$29:$AB$361,0))) -> Pegfilgrastim | G7: =IF($O7="","",INDEX(Scoring!$AG$29:$AG$361,MATCH($O7,Scoring!$AB$29:$AB$361,0))) -> Pelgraz | H7: =IF($O7="","",INDEX(Scoring!$C$29:$C$361,MATCH($O7,Scoring!$AB$29:$AB$361,0))) -> Oncology support: prevents low white cell counts after chemotherapy | I7: =IF($O7="","",INDEX(Scoring!$I$29:$I$361,MATCH($O7,Scoring!$AB$29:$AB$361,0))) -> Prefilled syringe | J7: =IF($O7="","",INDEX(Scoring!$Z$29:$Z$361,MATCH($O7,Scoring!$AB$29:$AB$361,0))) -> 6 mg/0.6 mL pre-filled syringe | K7: =IF($O7="","",IF(INDEX(Scoring!$D$29:$D$361,MATCH($O7,Scoring!$AB$29:$AB$361,0))="",INDEX(Scoring!$AF$29:$AF$361,MATCH($O7,Scoring!$AB$29:$AB$361,0)),INDEX(Scoring!$D$29:$D$361,MATCH($O7,Scoring!$AB$29:$AB$361,0)))) -> 907.38 | L7: =IF($O7="","",INDEX(Scoring!$M$29:$M$361,MATCH($O7,Scoring!$AB$29:$AB$361,0))) -> 155 | M7: =IF($O7="","",INDEX(Scoring!$F$29:$F$361,MATCH($O7,Scoring!$AB$29:$AB$361,0))) -> 22036.1 | N7: =IF($O7="","",INDEX(Scoring!$AI$29:$AI$361,MATCH($O7,Scoring!$AB$29:$AB$361,0))) -> UK | EU/EEA: all 30 countries | O7: =IFERROR(SMALL(Scoring!$AB$29:$AB$361,3),"") -> 1003
A8: =IF($O8="","",INT($O8/1000)) -> 1 | B8: =IF($O8="","",INDEX(Scoring!$A$29:$A$361,MATCH($O8,Scoring!$AB$29:$AB$361,0))) -> Intas | C8: =IF($O8="","",IF(INDEX(Scoring!$P$29:$P$361,MATCH($O8,Scoring!$AB$29:$AB$361,0))="","–",INDEX(Scoring!$P$29:$P$361,MATCH($O8,Scoring!$AB$29:$AB$361,0)))) -> 4 | D8: =IF($O8="","",INDEX(Scoring!$Q$29:$Q$361,MATCH($O8,Scoring!$AB$29:$AB$361,0))) -> Priority 1 | E8: =IF($O8="","",INDEX(Scoring!$AJ$29:$AJ$361,MATCH($O8,Scoring!$AB$29:$AB$361,0))) -> High price · high volume | F8: =IF($O8="","",INDEX(Scoring!$B$29:$B$361,MATCH($O8,Scoring!$AB$29:$AB$361,0))) -> Methotrexate | G8: =IF($O8="","",INDEX(Scoring!$AG$29:$AG$361,MATCH($O8,Scoring!$AB$29:$AB$361,0))) -> Methotrexate; Methotrexate Subcutaneous; Methotrexate Intas | H8: =IF($O8="","",INDEX(Scoring!$C$29:$C$361,MATCH($O8,Scoring!$AB$29:$AB$361,0))) -> Oncology and immunology: leukaemia, lymphoma, bone cancer, rheumatoid arthritis, psoriasis | I8: =IF($O8="","",INDEX(Scoring!$I$29:$I$361,MATCH($O8,Scoring!$AB$29:$AB$361,0))) -> Vial, Prefilled syringe | J8: =IF($O8="","",INDEX(Scoring!$Z$29:$Z$361,MATCH($O8,Scoring!$AB$29:$AB$361,0))) -> 50 mg/2 mL vial; 500 mg/20 mL vial; 1000 mg/40 mL vial; 10 mg/0.2 mL pre-filled syringe (+2 more) | K8: =IF($O8="","",IF(INDEX(Scoring!$D$29:$D$361,MATCH($O8,Scoring!$AB$29:$AB$361,0))="",INDEX(Scoring!$AF$29:$AF$361,MATCH($O8,Scoring!$AB$29:$AB$361,0)),INDEX(Scoring!$D$29:$D$361,MATCH($O8,Scoring!$AB$29:$AB$361,0)))) -> 50.77 | L8: =IF($O8="","",INDEX(Scoring!$M$29:$M$361,MATCH($O8,Scoring!$AB$29:$AB$361,0))) -> 996 | M8: =IF($O8="","",INDEX(Scoring!$F$29:$F$361,MATCH($O8,Scoring!$AB$29:$AB$361,0))) -> 13045.6 | N8: =IF($O8="","",INDEX(Scoring!$AI$29:$AI$361,MATCH($O8,Scoring!$AB$29:$AB$361,0))) -> UK, Canada, Australia, UK-NI | EU/EEA (25): Germany, France, Netherlands, Belgium + 21 more | O8: =IFERROR(SMALL(Scoring!$AB$29:$AB$361,4),"") -> 1004
A9: =IF($O9="","",INT($O9/1000)) -> 1 | B9: =IF($O9="","",INDEX(Scoring!$A$29:$A$361,MATCH($O9,Scoring!$AB$29:$AB$361,0))) -> Intas | C9: =IF($O9="","",IF(INDEX(Scoring!$P$29:$P$361,MATCH($O9,Scoring!$AB$29:$AB$361,0))="","–",INDEX(Scoring!$P$29:$P$361,MATCH($O9,Scoring!$AB$29:$AB$361,0)))) -> 5 | D9: =IF($O9="","",INDEX(Scoring!$Q$29:$Q$361,MATCH($O9,Scoring!$AB$29:$AB$361,0))) -> Priority 1 | E9: =IF($O9="","",INDEX(Scoring!$AJ$29:$AJ$361,MATCH($O9,Scoring!$AB$29:$AB$361,0))) -> High price · high volume | F9: =IF($O9="","",INDEX(Scoring!$B$29:$B$361,MATCH($O9,Scoring!$AB$29:$AB$361,0))) -> Fulvestrant | G9: =IF($O9="","",INDEX(Scoring!$AG$29:$AG$361,MATCH($O9,Scoring!$AB$29:$AB$361,0))) -> Fulvestrant; Fulvestrant Accord; Fulvestrant Intas (+1 more) | H9: =IF($O9="","",INDEX(Scoring!$C$29:$C$361,MATCH($O9,Scoring!$AB$29:$AB$361,0))) -> Oncology: hormone receptor-positive advanced breast cancer | I9: =IF($O9="","",INDEX(Scoring!$I$29:$I$361,MATCH($O9,Scoring!$AB$29:$AB$361,0))) -> Prefilled syringe | J9: =IF($O9="","",INDEX(Scoring!$Z$29:$Z$361,MATCH($O9,Scoring!$AB$29:$AB$361,0))) -> 250 mg/5 mL pre-filled syringe | K9: =IF($O9="","",IF(INDEX(Scoring!$D$29:$D$361,MATCH($O9,Scoring!$AB$29:$AB$361,0))="",INDEX(Scoring!$AF$29:$AF$361,MATCH($O9,Scoring!$AB$29:$AB$361,0)),INDEX(Scoring!$D$29:$D$361,MATCH($O9,Scoring!$AB$29:$AB$361,0)))) -> 246.46 | L9: =IF($O9="","",INDEX(Scoring!$M$29:$M$361,MATCH($O9,Scoring!$AB$29:$AB$361,0))) -> 146 | M9: =IF($O9="","",INDEX(Scoring!$F$29:$F$361,MATCH($O9,Scoring!$AB$29:$AB$361,0))) -> 11366.1 | N9: =IF($O9="","",INDEX(Scoring!$AI$29:$AI$361,MATCH($O9,Scoring!$AB$29:$AB$361,0))) -> US, UK, Australia, South Africa, UK-NI | EU/EEA (25): Germany, France, Netherlands, Belgium + 21 more | O9: =IFERROR(SMALL(Scoring!$AB$29:$AB$361,5),"") -> 1005
A10: =IF($O10="","",INT($O10/1000)) -> 1 | B10: =IF($O10="","",INDEX(Scoring!$A$29:$A$361,MATCH($O10,Scoring!$AB$29:$AB$361,0))) -> Intas | C10: =IF($O10="","",IF(INDEX(Scoring!$P$29:$P$361,MATCH($O10,Scoring!$AB$29:$AB$361,0))="","–",INDEX(Scoring!$P$29:$P$361,MATCH($O10,Scoring!$AB$29:$AB$361,0)))) -> 6 | D10: =IF($O10="","",INDEX(Scoring!$Q$29:$Q$361,MATCH($O10,Scoring!$AB$29:$AB$361,0))) -> Priority 1 | E10: =IF($O10="","",INDEX(Scoring!$AJ$29:$AJ$361,MATCH($O10,Scoring!$AB$29:$AB$361,0))) -> High price · high volume | F10: =IF($O10="","",INDEX(Scoring!$B$29:$B$361,MATCH($O10,Scoring!$AB$29:$AB$361,0))) -> Phenylephrine | G10: =IF($O10="","",INDEX(Scoring!$AG$29:$AG$361,MATCH($O10,Scoring!$AB$29:$AB$361,0))) -> Phenylephrine Accord; Phenylcord | H10: =IF($O10="","",INDEX(Scoring!$C$29:$C$361,MATCH($O10,Scoring!$AB$29:$AB$361,0))) -> Anaesthesia: low blood pressure during anaesthesia | I10: =IF($O10="","",INDEX(Scoring!$I$29:$I$361,MATCH($O10,Scoring!$AB$29:$AB$361,0))) -> Vial | J10: =IF($O10="","",INDEX(Scoring!$Z$29:$Z$361,MATCH($O10,Scoring!$AB$29:$AB$361,0))) -> 10 mg/1 mL vial; 100 mg/10 mL vial | K10: =IF($O10="","",IF(INDEX(Scoring!$D$29:$D$361,MATCH($O10,Scoring!$AB$29:$AB$361,0))="",INDEX(Scoring!$AF$29:$AF$361,MATCH($O10,Scoring!$AB$29:$AB$361,0)),INDEX(Scoring!$D$29:$D$361,MATCH($O10,Scoring!$AB$29:$AB$361,0)))) -> 32.6 | L10: =IF($O10="","",INDEX(Scoring!$M$29:$M$361,MATCH($O10,Scoring!$AB$29:$AB$361,0))) -> 226 | M10: =IF($O10="","",INDEX(Scoring!$F$29:$F$361,MATCH($O10,Scoring!$AB$29:$AB$361,0))) -> 5695.2 | N10: =IF($O10="","",INDEX(Scoring!$AI$29:$AI$361,MATCH($O10,Scoring!$AB$29:$AB$361,0))) -> Australia, South Africa | O10: =IFERROR(SMALL(Scoring!$AB$29:$AB$361,6),"") -> 1006
A11: =IF($O11="","",INT($O11/1000)) -> 1 | B11: =IF($O11="","",INDEX(Scoring!$A$29:$A$361,MATCH($O11,Scoring!$AB$29:$AB$361,0))) -> Intas | C11: =IF($O11="","",IF(INDEX(Scoring!$P$29:$P$361,MATCH($O11,Scoring!$AB$29:$AB$361,0))="","–",INDEX(Scoring!$P$29:$P$361,MATCH($O11,Scoring!$AB$29:$AB$361,0)))) -> 7 | D11: =IF($O11="","",INDEX(Scoring!$Q$29:$Q$361,MATCH($O11,Scoring!$AB$29:$AB$361,0))) -> Priority 1 | E11: =IF($O11="","",INDEX(Scoring!$AJ$29:$AJ$361,MATCH($O11,Scoring!$AB$29:$AB$361,0))) -> High price · high volume | F11: =IF($O11="","",INDEX(Scoring!$B$29:$B$361,MATCH($O11,Scoring!$AB$29:$AB$361,0))) -> Epinephrine (Adrenaline) | G11: =IF($O11="","",INDEX(Scoring!$AG$29:$AG$361,MATCH($O11,Scoring!$AB$29:$AB$361,0))) -> Adrenaline Accord | H11: =IF($O11="","",INDEX(Scoring!$C$29:$C$361,MATCH($O11,Scoring!$AB$29:$AB$361,0))) -> Critical care: anaphylaxis, cardiac arrest, shock | I11: =IF($O11="","",INDEX(Scoring!$I$29:$I$361,MATCH($O11,Scoring!$AB$29:$AB$361,0))) -> Prefilled syringe | J11: =IF($O11="","",INDEX(Scoring!$Z$29:$Z$361,MATCH($O11,Scoring!$AB$29:$AB$361,0))) -> 1 mg/10 mL pre-filled syringe | K11: =IF($O11="","",IF(INDEX(Scoring!$D$29:$D$361,MATCH($O11,Scoring!$AB$29:$AB$361,0))="",INDEX(Scoring!$AF$29:$AF$361,MATCH($O11,Scoring!$AB$29:$AB$361,0)),INDEX(Scoring!$D$29:$D$361,MATCH($O11,Scoring!$AB$29:$AB$361,0)))) -> 28.67 | L11: =IF($O11="","",INDEX(Scoring!$M$29:$M$361,MATCH($O11,Scoring!$AB$29:$AB$361,0))) -> 799 | M11: =IF($O11="","",INDEX(Scoring!$F$29:$F$361,MATCH($O11,Scoring!$AB$29:$AB$361,0))) -> 4049.5 | N11: =IF($O11="","",INDEX(Scoring!$AI$29:$AI$361,MATCH($O11,Scoring!$AB$29:$AB$361,0))) -> EU/EEA (3): France, Netherlands, Portugal | O11: =IFERROR(SMALL(Scoring!$AB$29:$AB$361,7),"") -> 1007
A12: =IF($O12="","",INT($O12/1000)) -> 1 | B12: =IF($O12="","",INDEX(Scoring!$A$29:$A$361,MATCH($O12,Scoring!$AB$29:$AB$361,0))) -> Intas | C12: =IF($O12="","",IF(INDEX(Scoring!$P$29:$P$361,MATCH($O12,Scoring!$AB$29:$AB$361,0))="","–",INDEX(Scoring!$P$29:$P$361,MATCH($O12,Scoring!$AB$29:$AB$361,0)))) -> 8 | D12: =IF($O12="","",INDEX(Scoring!$Q$29:$Q$361,MATCH($O12,Scoring!$AB$29:$AB$361,0))) -> Priority 1 | E12: =IF($O12="","",INDEX(Scoring!$AJ$29:$AJ$361,MATCH($O12,Scoring!$AB$29:$AB$361,0))) -> High price · high volume | F12: =IF($O12="","",INDEX(Scoring!$B$29:$B$361,MATCH($O12,Scoring!$AB$29:$AB$361,0))) -> Bleomycin | G12: =IF($O12="","",INDEX(Scoring!$AG$29:$AG$361,MATCH($O12,Scoring!$AB$29:$AB$361,0))) -> Bleomycin; Bleomicina Accord; Bleomycin Accord | H12: =IF($O12="","",INDEX(Scoring!$C$29:$C$361,MATCH($O12,Scoring!$AB$29:$AB$361,0))) -> Oncology: Hodgkin lymphoma, testicular and squamous cell cancers | I12: =IF($O12="","",INDEX(Scoring!$I$29:$I$361,MATCH($O12,Scoring!$AB$29:$AB$361,0))) -> Vial | J12: =IF($O12="","",INDEX(Scoring!$Z$29:$Z$361,MATCH($O12,Scoring!$AB$29:$AB$361,0))) -> 15000 IU powder vial | K12: =IF($O12="","",IF(INDEX(Scoring!$D$29:$D$361,MATCH($O12,Scoring!$AB$29:$AB$361,0))="",INDEX(Scoring!$AF$29:$AF$361,MATCH($O12,Scoring!$AB$29:$AB$361,0)),INDEX(Scoring!$D$29:$D$361,MATCH($O12,Scoring!$AB$29:$AB$361,0)))) -> 50.27 | L12: =IF($O12="","",INDEX(Scoring!$M$29:$M$361,MATCH($O12,Scoring!$AB$29:$AB$361,0))) -> 441 | M12: =IF($O12="","",INDEX(Scoring!$F$29:$F$361,MATCH($O12,Scoring!$AB$29:$AB$361,0))) -> 3973.7 | N12: =IF($O12="","",INDEX(Scoring!$AI$29:$AI$361,MATCH($O12,Scoring!$AB$29:$AB$361,0))) -> UK, Australia, UK-NI | EU/EEA (14): Germany, France, Netherlands, Belgium + 10 more | O12: =IFERROR(SMALL(Scoring!$AB$29:$AB$361,8),"") -> 1008
A13: =IF($O13="","",INT($O13/1000)) -> 1 | B13: =IF($O13="","",INDEX(Scoring!$A$29:$A$361,MATCH($O13,Scoring!$AB$29:$AB$361,0))) -> Intas | C13: =IF($O13="","",IF(INDEX(Scoring!$P$29:$P$361,MATCH($O13,Scoring!$AB$29:$AB$361,0))="","–",INDEX(Scoring!$P$29:$P$361,MATCH($O13,Scoring!$AB$29:$AB$361,0)))) -> 9 | D13: =IF($O13="","",INDEX(Scoring!$Q$29:$Q$361,MATCH($O13,Scoring!$AB$29:$AB$361,0))) -> Priority 1 | E13: =IF($O13="","",INDEX(Scoring!$AJ$29:$AJ$361,MATCH($O13,Scoring!$AB$29:$AB$361,0))) -> High price · high volume | F13: =IF($O13="","",INDEX(Scoring!$B$29:$B$361,MATCH($O13,Scoring!$AB$29:$AB$361,0))) -> Denosumab | G13: =IF($O13="","",INDEX(Scoring!$AG$29:$AG$361,MATCH($O13,Scoring!$AB$29:$AB$361,0))) -> Jubereq; Dostiva | H13: =IF($O13="","",INDEX(Scoring!$C$29:$C$361,MATCH($O13,Scoring!$AB$29:$AB$361,0))) -> Bone health and oncology: bone metastases, osteoporosis | I13: =IF($O13="","",INDEX(Scoring!$I$29:$I$361,MATCH($O13,Scoring!$AB$29:$AB$361,0))) -> Vial | J13: =IF($O13="","",INDEX(Scoring!$Z$29:$Z$361,MATCH($O13,Scoring!$AB$29:$AB$361,0))) -> 120 mg/1.7 mL vial | K13: =IF($O13="","",IF(INDEX(Scoring!$D$29:$D$361,MATCH($O13,Scoring!$AB$29:$AB$361,0))="",INDEX(Scoring!$AF$29:$AF$361,MATCH($O13,Scoring!$AB$29:$AB$361,0)),INDEX(Scoring!$D$29:$D$361,MATCH($O13,Scoring!$AB$29:$AB$361,0)))) -> 162.77 | L13: =IF($O13="","",INDEX(Scoring!$M$29:$M$361,MATCH($O13,Scoring!$AB$29:$AB$361,0))) -> 314 | M13: =IF($O13="","",INDEX(Scoring!$F$29:$F$361,MATCH($O13,Scoring!$AB$29:$AB$361,0))) -> 3429.5 | N13: =IF($O13="","",INDEX(Scoring!$AI$29:$AI$361,MATCH($O13,Scoring!$AB$29:$AB$361,0))) -> UK, Australia | EU/EEA: all 30 countries | O13: =IFERROR(SMALL(Scoring!$AB$29:$AB$361,9),"") -> 1009
A14: =IF($O14="","",INT($O14/1000)) -> 1 | B14: =IF($O14="","",INDEX(Scoring!$A$29:$A$361,MATCH($O14,Scoring!$AB$29:$AB$361,0))) -> Intas | C14: =IF($O14="","",IF(INDEX(Scoring!$P$29:$P$361,MATCH($O14,Scoring!$AB$29:$AB$361,0))="","–",INDEX(Scoring!$P$29:$P$361,MATCH($O14,Scoring!$AB$29:$AB$361,0)))) -> 10 | D14: =IF($O14="","",INDEX(Scoring!$Q$29:$Q$361,MATCH($O14,Scoring!$AB$29:$AB$361,0))) -> Priority 2 | E14: =IF($O14="","",INDEX(Scoring!$AJ$29:$AJ$361,MATCH($O14,Scoring!$AB$29:$AB$361,0))) -> Lower price · high volume | F14: =IF($O14="","",INDEX(Scoring!$B$29:$B$361,MATCH($O14,Scoring!$AB$29:$AB$361,0))) -> Ceftriaxone | G14: =IF($O14="","",INDEX(Scoring!$AG$29:$AG$361,MATCH($O14,Scoring!$AB$29:$AB$361,0))) -> Ceftriaxone Accord | H14: =IF($O14="","",INDEX(Scoring!$C$29:$C$361,MATCH($O14,Scoring!$AB$29:$AB$361,0))) -> Anti-infective: pneumonia, meningitis, sepsis, gonorrhoea, typhoid | I14: =IF($O14="","",INDEX(Scoring!$I$29:$I$361,MATCH($O14,Scoring!$AB$29:$AB$361,0))) -> Not stated | J14: =IF($O14="","",INDEX(Scoring!$Z$29:$Z$361,MATCH($O14,Scoring!$AB$29:$AB$361,0))) -> 1 g (container not stated) | K14: =IF($O14="","",IF(INDEX(Scoring!$D$29:$D$361,MATCH($O14,Scoring!$AB$29:$AB$361,0))="",INDEX(Scoring!$AF$29:$AF$361,MATCH($O14,Scoring!$AB$29:$AB$361,0)),INDEX(Scoring!$D$29:$D$361,MATCH($O14,Scoring!$AB$29:$AB$361,0)))) -> 5.6 | L14: =IF($O14="","",INDEX(Scoring!$M$29:$M$361,MATCH($O14,Scoring!$AB$29:$AB$361,0))) -> 3110 | M14: =IF($O14="","",INDEX(Scoring!$F$29:$F$361,MATCH($O14,Scoring!$AB$29:$AB$361,0))) -> 93119.2 | N14: =IF($O14="","",INDEX(Scoring!$AI$29:$AI$361,MATCH($O14,Scoring!$AB$29:$AB$361,0))) -> EU/EEA (1): Italy | O14: =IFERROR(SMALL(Scoring!$AB$29:$AB$361,10),"") -> 1010
A15: =IF($O15="","",INT($O15/1000)) -> 1 | B15: =IF($O15="","",INDEX(Scoring!$A$29:$A$361,MATCH($O15,Scoring!$AB$29:$AB$361,0))) -> Intas | C15: =IF($O15="","",IF(INDEX(Scoring!$P$29:$P$361,MATCH($O15,Scoring!$AB$29:$AB$361,0))="","–",INDEX(Scoring!$P$29:$P$361,MATCH($O15,Scoring!$AB$29:$AB$361,0)))) -> 11 | D15: =IF($O15="","",INDEX(Scoring!$Q$29:$Q$361,MATCH($O15,Scoring!$AB$29:$AB$361,0))) -> Priority 2 | E15: =IF($O15="","",INDEX(Scoring!$AJ$29:$AJ$361,MATCH($O15,Scoring!$AB$29:$AB$361,0))) -> Lower price · high volume | F15: =IF($O15="","",INDEX(Scoring!$B$29:$B$361,MATCH($O15,Scoring!$AB$29:$AB$361,0))) -> Ondansetron | G15: =IF($O15="","",INDEX(Scoring!$AG$29:$AG$361,MATCH($O15,Scoring!$AB$29:$AB$361,0))) -> Ondansetron Hydrochloride; Ondansetron; Ondansetron Accord | H15: =IF($O15="","",INDEX(Scoring!$C$29:$C$361,MATCH($O15,Scoring!$AB$29:$AB$361,0))) -> Oncology support: nausea and vomiting from chemotherapy and surgery | I15: =IF($O15="","",INDEX(Scoring!$I$29:$I$361,MATCH($O15,Scoring!$AB$29:$AB$361,0))) -> Vial, Ampoule, Prefilled syringe | J15: =IF($O15="","",INDEX(Scoring!$Z$29:$Z$361,MATCH($O15,Scoring!$AB$29:$AB$361,0))) -> 40 mg/20 mL vial; 8 mg/4 mL pre-filled syringe; 4 mg/2 mL ampoule; 4 mg/2 mL pre-filled syringe | K15: =IF($O15="","",IF(INDEX(Scoring!$D$29:$D$361,MATCH($O15,Scoring!$AB$29:$AB$361,0))="",INDEX(Scoring!$AF$29:$AF$361,MATCH($O15,Scoring!$AB$29:$AB$361,0)),INDEX(Scoring!$D$29:$D$361,MATCH($O15,Scoring!$AB$29:$AB$361,0)))) -> 24.05 | L15: =IF($O15="","",INDEX(Scoring!$M$29:$M$361,MATCH($O15,Scoring!$AB$29:$AB$361,0))) -> 963 | M15: =IF($O15="","",INDEX(Scoring!$F$29:$F$361,MATCH($O15,Scoring!$AB$29:$AB$361,0))) -> 17590.5 | N15: =IF($O15="","",INDEX(Scoring!$AI$29:$AI$361,MATCH($O15,Scoring!$AB$29:$AB$361,0))) -> US, UK, Australia, UK-NI | EU/EEA (23): Germany, France, Netherlands, Belgium + 19 more | O15: =IFERROR(SMALL(Scoring!$AB$29:$AB$361,11),"") -> 1011
A16: =IF($O16="","",INT($O16/1000)) -> 1 | B16: =IF($O16="","",INDEX(Scoring!$A$29:$A$361,MATCH($O16,Scoring!$AB$29:$AB$361,0))) -> Intas | C16: =IF($O16="","",IF(INDEX(Scoring!$P$29:$P$361,MATCH($O16,Scoring!$AB$29:$AB$361,0))="","–",INDEX(Scoring!$P$29:$P$361,MATCH($O16,Scoring!$AB$29:$AB$361,0)))) -> 12 | D16: =IF($O16="","",INDEX(Scoring!$Q$29:$Q$361,MATCH($O16,Scoring!$AB$29:$AB$361,0))) -> Priority 2 | E16: =IF($O16="","",INDEX(Scoring!$AJ$29:$AJ$361,MATCH($O16,Scoring!$AB$29:$AB$361,0))) -> High price · lower volume | F16: =IF($O16="","",INDEX(Scoring!$B$29:$B$361,MATCH($O16,Scoring!$AB$29:$AB$361,0))) -> Plerixafor | G16: =IF($O16="","",INDEX(Scoring!$AG$29:$AG$361,MATCH($O16,Scoring!$AB$29:$AB$361,0))) -> Plerixafor; Plerixafor Accord | H16: =IF($O16="","",INDEX(Scoring!$C$29:$C$361,MATCH($O16,Scoring!$AB$29:$AB$361,0))) -> Oncology support: stem cell mobilisation in myeloma and lymphoma | I16: =IF($O16="","",INDEX(Scoring!$I$29:$I$361,MATCH($O16,Scoring!$AB$29:$AB$361,0))) -> Vial | J16: =IF($O16="","",INDEX(Scoring!$Z$29:$Z$361,MATCH($O16,Scoring!$AB$29:$AB$361,0))) -> 24 mg/1.2 mL vial | K16: =IF($O16="","",IF(INDEX(Scoring!$D$29:$D$361,MATCH($O16,Scoring!$AB$29:$AB$361,0))="",INDEX(Scoring!$AF$29:$AF$361,MATCH($O16,Scoring!$AB$29:$AB$361,0)),INDEX(Scoring!$D$29:$D$361,MATCH($O16,Scoring!$AB$29:$AB$361,0)))) -> 4779 | L16: =IF($O16="","",INDEX(Scoring!$M$29:$M$361,MATCH($O16,Scoring!$AB$29:$AB$361,0))) -> 47 | M16: =IF($O16="","",INDEX(Scoring!$F$29:$F$361,MATCH($O16,Scoring!$AB$29:$AB$361,0))) -> 7904.7 | N16: =IF($O16="","",INDEX(Scoring!$AI$29:$AI$361,MATCH($O16,Scoring!$AB$29:$AB$361,0))) -> UK, Australia | EU/EEA: all 30 countries | O16: =IFERROR(SMALL(Scoring!$AB$29:$AB$361,12),"") -> 1012
A17: =IF($O17="","",INT($O17/1000)) -> 1 | B17: =IF($O17="","",INDEX(Scoring!$A$29:$A$361,MATCH($O17,Scoring!$AB$29:$AB$361,0))) -> Intas | C17: =IF($O17="","",IF(INDEX(Scoring!$P$29:$P$361,MATCH($O17,Scoring!$AB$29:$AB$361,0))="","–",INDEX(Scoring!$P$29:$P$361,MATCH($O17,Scoring!$AB$29:$AB$361,0)))) -> 13 | D17: =IF($O17="","",INDEX(Scoring!$Q$29:$Q$361,MATCH($O17,Scoring!$AB$29:$AB$361,0))) -> Priority 2 | E17: =IF($O17="","",INDEX(Scoring!$AJ$29:$AJ$361,MATCH($O17,Scoring!$AB$29:$AB$361,0))) -> Lower price · high volume | F17: =IF($O17="","",INDEX(Scoring!$B$29:$B$361,MATCH($O17,Scoring!$AB$29:$AB$361,0))) -> Cytarabine | G17: =IF($O17="","",INDEX(Scoring!$AG$29:$AG$361,MATCH($O17,Scoring!$AB$29:$AB$361,0))) -> Cytarabine; Cytarabine Accord; Cytarabine ACC | H17: =IF($O17="","",INDEX(Scoring!$C$29:$C$361,MATCH($O17,Scoring!$AB$29:$AB$361,0))) -> Oncology: acute myeloid and acute lymphoblastic leukaemia | I17: =IF($O17="","",INDEX(Scoring!$I$29:$I$361,MATCH($O17,Scoring!$AB$29:$AB$361,0))) -> Vial | J17: =IF($O17="","",INDEX(Scoring!$Z$29:$Z$361,MATCH($O17,Scoring!$AB$29:$AB$361,0))) -> 100 mg/5 mL vial; 4000 mg/40 mL vial; 2000 mg/20 mL vial; 500 mg/5 mL vial (+3 more) | K17: =IF($O17="","",IF(INDEX(Scoring!$D$29:$D$361,MATCH($O17,Scoring!$AB$29:$AB$361,0))="",INDEX(Scoring!$AF$29:$AF$361,MATCH($O17,Scoring!$AB$29:$AB$361,0)),INDEX(Scoring!$D$29:$D$361,MATCH($O17,Scoring!$AB$29:$AB$361,0)))) -> 6.7 | L17: =IF($O17="","",INDEX(Scoring!$M$29:$M$361,MATCH($O17,Scoring!$AB$29:$AB$361,0))) -> 799 | M17: =IF($O17="","",INDEX(Scoring!$F$29:$F$361,MATCH($O17,Scoring!$AB$29:$AB$361,0))) -> 7739 | N17: =IF($O17="","",INDEX(Scoring!$AI$29:$AI$361,MATCH($O17,Scoring!$AB$29:$AB$361,0))) -> UK, Australia, UK-NI | EU/EEA (25): Germany, France, Netherlands, Belgium + 21 more | O17: =IFERROR(SMALL(Scoring!$AB$29:$AB$361,13),"") -> 1013
A18: =IF($O18="","",INT($O18/1000)) -> 1 | B18: =IF($O18="","",INDEX(Scoring!$A$29:$A$361,MATCH($O18,Scoring!$AB$29:$AB$361,0))) -> Intas | C18: =IF($O18="","",IF(INDEX(Scoring!$P$29:$P$361,MATCH($O18,Scoring!$AB$29:$AB$361,0))="","–",INDEX(Scoring!$P$29:$P$361,MATCH($O18,Scoring!$AB$29:$AB$361,0)))) -> 14 | D18: =IF($O18="","",INDEX(Scoring!$Q$29:$Q$361,MATCH($O18,Scoring!$AB$29:$AB$361,0))) -> Priority 2 | E18: =IF($O18="","",INDEX(Scoring!$AJ$29:$AJ$361,MATCH($O18,Scoring!$AB$29:$AB$361,0))) -> Lower price · high volume | F18: =IF($O18="","",INDEX(Scoring!$B$29:$B$361,MATCH($O18,Scoring!$AB$29:$AB$361,0))) -> Atropine | G18: =IF($O18="","",INDEX(Scoring!$AG$29:$AG$361,MATCH($O18,Scoring!$AB$29:$AB$361,0))) -> Atropine Sulfate; Atropin Accord; Atropina Accord | H18: =IF($O18="","",INDEX(Scoring!$C$29:$C$361,MATCH($O18,Scoring!$AB$29:$AB$361,0))) -> Critical care: slow heart rate, pre-anaesthesia, organophosphate poisoning | I18: =IF($O18="","",INDEX(Scoring!$I$29:$I$361,MATCH($O18,Scoring!$AB$29:$AB$361,0))) -> Vial, Prefilled syringe | J18: =IF($O18="","",INDEX(Scoring!$Z$29:$Z$361,MATCH($O18,Scoring!$AB$29:$AB$361,0))) -> 0.25 mg/5 mL pre-filled syringe; 0.4 mg/1 mL vial; 0.5 mg/5 mL pre-filled syringe; 1 mg/10 mL pre-filled syringe (+3 more) | K18: =IF($O18="","",IF(INDEX(Scoring!$D$29:$D$361,MATCH($O18,Scoring!$AB$29:$AB$361,0))="",INDEX(Scoring!$AF$29:$AF$361,MATCH($O18,Scoring!$AB$29:$AB$361,0)),INDEX(Scoring!$D$29:$D$361,MATCH($O18,Scoring!$AB$29:$AB$361,0)))) -> 16.48 | L18: =IF($O18="","",INDEX(Scoring!$M$29:$M$361,MATCH($O18,Scoring!$AB$29:$AB$361,0))) -> 715 | M18: =IF($O18="","",INDEX(Scoring!$F$29:$F$361,MATCH($O18,Scoring!$AB$29:$AB$361,0))) -> 6805 | N18: =IF($O18="","",INDEX(Scoring!$AI$29:$AI$361,MATCH($O18,Scoring!$AB$29:$AB$361,0))) -> US, UK, UK-NI | EU/EEA (13): Germany, France, Netherlands, Austria + 9 more | O18: =IFERROR(SMALL(Scoring!$AB$29:$AB$361,14),"") -> 1014
A19: =IF($O19="","",INT($O19/1000)) -> 1 | B19: =IF($O19="","",INDEX(Scoring!$A$29:$A$361,MATCH($O19,Scoring!$AB$29:$AB$361,0))) -> Intas | C19: =IF($O19="","",IF(INDEX(Scoring!$P$29:$P$361,MATCH($O19,Scoring!$AB$29:$AB$361,0))="","–",INDEX(Scoring!$P$29:$P$361,MATCH($O19,Scoring!$AB$29:$AB$361,0)))) -> 15 | D19: =IF($O19="","",INDEX(Scoring!$Q$29:$Q$361,MATCH($O19,Scoring!$AB$29:$AB$361,0))) -> Priority 2 | E19: =IF($O19="","",INDEX(Scoring!$AJ$29:$AJ$361,MATCH($O19,Scoring!$AB$29:$AB$361,0))) -> High price · lower volume | F19: =IF($O19="","",INDEX(Scoring!$B$29:$B$361,MATCH($O19,Scoring!$AB$29:$AB$361,0))) -> Teicoplanin | G19: =IF($O19="","",INDEX(Scoring!$AG$29:$AG$361,MATCH($O19,Scoring!$AB$29:$AB$361,0))) -> Teicoplanina Accord | H19: =IF($O19="","",INDEX(Scoring!$C$29:$C$361,MATCH($O19,Scoring!$AB$29:$AB$361,0))) -> Anti-infective: MRSA and serious Gram-positive infections | I19: =IF($O19="","",INDEX(Scoring!$I$29:$I$361,MATCH($O19,Scoring!$AB$29:$AB$361,0))) -> Vial | J19: =IF($O19="","",INDEX(Scoring!$Z$29:$Z$361,MATCH($O19,Scoring!$AB$29:$AB$361,0))) -> 200 mg powder vial | K19: =IF($O19="","",IF(INDEX(Scoring!$D$29:$D$361,MATCH($O19,Scoring!$AB$29:$AB$361,0))="",INDEX(Scoring!$AF$29:$AF$361,MATCH($O19,Scoring!$AB$29:$AB$361,0)),INDEX(Scoring!$D$29:$D$361,MATCH($O19,Scoring!$AB$29:$AB$361,0)))) -> 35.27 | L19: =IF($O19="","",INDEX(Scoring!$M$29:$M$361,MATCH($O19,Scoring!$AB$29:$AB$361,0))) -> 99 | M19: =IF($O19="","",INDEX(Scoring!$F$29:$F$361,MATCH($O19,Scoring!$AB$29:$AB$361,0))) -> 6632.6 | N19: =IF($O19="","",INDEX(Scoring!$AI$29:$AI$361,MATCH($O19,Scoring!$AB$29:$AB$361,0))) -> EU/EEA (3): Austria, Portugal, Spain | O19: =IFERROR(SMALL(Scoring!$AB$29:$AB$361,15),"") -> 1015
A20: =IF($O20="","",INT($O20/1000)) -> 1 | B20: =IF($O20="","",INDEX(Scoring!$A$29:$A$361,MATCH($O20,Scoring!$AB$29:$AB$361,0))) -> Intas | C20: =IF($O20="","",IF(INDEX(Scoring!$P$29:$P$361,MATCH($O20,Scoring!$AB$29:$AB$361,0))="","–",INDEX(Scoring!$P$29:$P$361,MATCH($O20,Scoring!$AB$29:$AB$361,0)))) -> 16 | D20: =IF($O20="","",INDEX(Scoring!$Q$29:$Q$361,MATCH($O20,Scoring!$AB$29:$AB$361,0))) -> Priority 2 | E20: =IF($O20="","",INDEX(Scoring!$AJ$29:$AJ$361,MATCH($O20,Scoring!$AB$29:$AB$361,0))) -> Lower price · high volume | F20: =IF($O20="","",INDEX(Scoring!$B$29:$B$361,MATCH($O20,Scoring!$AB$29:$AB$361,0))) -> Cefepime | G20: =IF($O20="","",INDEX(Scoring!$AG$29:$AG$361,MATCH($O20,Scoring!$AB$29:$AB$361,0))) -> Cefepim Accord; Cefepime Accord | H20: =IF($O20="","",INDEX(Scoring!$C$29:$C$361,MATCH($O20,Scoring!$AB$29:$AB$361,0))) -> Anti-infective: hospital Gram-negative infections, febrile neutropenia | I20: =IF($O20="","",INDEX(Scoring!$I$29:$I$361,MATCH($O20,Scoring!$AB$29:$AB$361,0))) -> Vial | J20: =IF($O20="","",INDEX(Scoring!$Z$29:$Z$361,MATCH($O20,Scoring!$AB$29:$AB$361,0))) -> 1 g powder vial | K20: =IF($O20="","",IF(INDEX(Scoring!$D$29:$D$361,MATCH($O20,Scoring!$AB$29:$AB$361,0))="",INDEX(Scoring!$AF$29:$AF$361,MATCH($O20,Scoring!$AB$29:$AB$361,0)),INDEX(Scoring!$D$29:$D$361,MATCH($O20,Scoring!$AB$29:$AB$361,0)))) -> 9.65 | L20: =IF($O20="","",INDEX(Scoring!$M$29:$M$361,MATCH($O20,Scoring!$AB$29:$AB$361,0))) -> 288 | M20: =IF($O20="","",INDEX(Scoring!$F$29:$F$361,MATCH($O20,Scoring!$AB$29:$AB$361,0))) -> 6294.9 | N20: =IF($O20="","",INDEX(Scoring!$AI$29:$AI$361,MATCH($O20,Scoring!$AB$29:$AB$361,0))) -> EU/EEA (4): Germany, France, Croatia, Portugal | O20: =IFERROR(SMALL(Scoring!$AB$29:$AB$361,16),"") -> 1016
A21: =IF($O21="","",INT($O21/1000)) -> 1 | B21: =IF($O21="","",INDEX(Scoring!$A$29:$A$361,MATCH($O21,Scoring!$AB$29:$AB$361,0))) -> Intas | C21: =IF($O21="","",IF(INDEX(Scoring!$P$29:$P$361,MATCH($O21,Scoring!$AB$29:$AB$361,0))="","–",INDEX(Scoring!$P$29:$P$361,MATCH($O21,Scoring!$AB$29:$AB$361,0)))) -> 17 | D21: =IF($O21="","",INDEX(Scoring!$Q$29:$Q$361,MATCH($O21,Scoring!$AB$29:$AB$361,0))) -> Priority 2 | E21: =IF($O21="","",INDEX(Scoring!$AJ$29:$AJ$361,MATCH($O21,Scoring!$AB$29:$AB$361,0))) -> Lower price · high volume | F21: =IF($O21="","",INDEX(Scoring!$B$29:$B$361,MATCH($O21,Scoring!$AB$29:$AB$361,0))) -> Midazolam | G21: =IF($O21="","",INDEX(Scoring!$AG$29:$AG$361,MATCH($O21,Scoring!$AB$29:$AB$361,0))) -> Midazolam Accord; Intas Midazolam | H21: =IF($O21="","",INDEX(Scoring!$C$29:$C$361,MATCH($O21,Scoring!$AB$29:$AB$361,0))) -> Anaesthesia: sedation for procedures and ICU, anaesthesia induction, seizures | I21: =IF($O21="","",INDEX(Scoring!$I$29:$I$361,MATCH($O21,Scoring!$AB$29:$AB$361,0))) -> Ampoule, Prefilled syringe | J21: =IF($O21="","",INDEX(Scoring!$Z$29:$Z$361,MATCH($O21,Scoring!$AB$29:$AB$361,0))) -> 50 mg/10 mL pre-filled syringe; 5 mg/5 mL pre-filled syringe; 15 mg/3 mL ampoule | K21: =IF($O21="","",IF(INDEX(Scoring!$D$29:$D$361,MATCH($O21,Scoring!$AB$29:$AB$361,0))="",INDEX(Scoring!$AF$29:$AF$361,MATCH($O21,Scoring!$AB$29:$AB$361,0)),INDEX(Scoring!$D$29:$D$361,MATCH($O21,Scoring!$AB$29:$AB$361,0)))) -> 11.33 | L21: =IF($O21="","",INDEX(Scoring!$M$29:$M$361,MATCH($O21,Scoring!$AB$29:$AB$361,0))) -> 177 | M21: =IF($O21="","",INDEX(Scoring!$F$29:$F$361,MATCH($O21,Scoring!$AB$29:$AB$361,0))) -> 4675.1 | N21: =IF($O21="","",INDEX(Scoring!$AI$29:$AI$361,MATCH($O21,Scoring!$AB$29:$AB$361,0))) -> Australia, UK-NI | EU/EEA (22): Germany, France, Netherlands, Belgium + 18 more | O21: =IFERROR(SMALL(Scoring!$AB$29:$AB$361,17),"") -> 1017
A22: =IF($O22="","",INT($O22/1000)) -> 1 | B22: =IF($O22="","",INDEX(Scoring!$A$29:$A$361,MATCH($O22,Scoring!$AB$29:$AB$361,0))) -> Intas | C22: =IF($O22="","",IF(INDEX(Scoring!$P$29:$P$361,MATCH($O22,Scoring!$AB$29:$AB$361,0))="","–",INDEX(Scoring!$P$29:$P$361,MATCH($O22,Scoring!$AB$29:$AB$361,0)))) -> 18 | D22: =IF($O22="","",INDEX(Scoring!$Q$29:$Q$361,MATCH($O22,Scoring!$AB$29:$AB$361,0))) -> Priority 2 | E22: =IF($O22="","",INDEX(Scoring!$AJ$29:$AJ$361,MATCH($O22,Scoring!$AB$29:$AB$361,0))) -> Lower price · high volume | F22: =IF($O22="","",INDEX(Scoring!$B$29:$B$361,MATCH($O22,Scoring!$AB$29:$AB$361,0))) -> Succinylcholine (Suxamethonium) | G22: =IF($O22="","",INDEX(Scoring!$AG$29:$AG$361,MATCH($O22,Scoring!$AB$29:$AB$361,0))) -> Suxamethonium Intas | H22: =IF($O22="","",INDEX(Scoring!$C$29:$C$361,MATCH($O22,Scoring!$AB$29:$AB$361,0))) -> Anaesthesia: muscle relaxant for rapid intubation | I22: =IF($O22="","",INDEX(Scoring!$I$29:$I$361,MATCH($O22,Scoring!$AB$29:$AB$361,0))) -> Prefilled syringe | J22: =IF($O22="","",INDEX(Scoring!$Z$29:$Z$361,MATCH($O22,Scoring!$AB$29:$AB$361,0))) -> 100 mg/2 mL pre-filled syringe | K22: =IF($O22="","",IF(INDEX(Scoring!$D$29:$D$361,MATCH($O22,Scoring!$AB$29:$AB$361,0))="",INDEX(Scoring!$AF$29:$AF$361,MATCH($O22,Scoring!$AB$29:$AB$361,0)),INDEX(Scoring!$D$29:$D$361,MATCH($O22,Scoring!$AB$29:$AB$361,0)))) -> 5.12 | L22: =IF($O22="","",INDEX(Scoring!$M$29:$M$361,MATCH($O22,Scoring!$AB$29:$AB$361,0))) -> 286 | M22: =IF($O22="","",INDEX(Scoring!$F$29:$F$361,MATCH($O22,Scoring!$AB$29:$AB$361,0))) -> 3067.4 | N22: =IF($O22="","",INDEX(Scoring!$AI$29:$AI$361,MATCH($O22,Scoring!$AB$29:$AB$361,0))) -> Australia | O22: =IFERROR(SMALL(Scoring!$AB$29:$AB$361,18),"") -> 1018
A23: =IF($O23="","",INT($O23/1000)) -> 1 | B23: =IF($O23="","",INDEX(Scoring!$A$29:$A$361,MATCH($O23,Scoring!$AB$29:$AB$361,0))) -> Intas | C23: =IF($O23="","",IF(INDEX(Scoring!$P$29:$P$361,MATCH($O23,Scoring!$AB$29:$AB$361,0))="","–",INDEX(Scoring!$P$29:$P$361,MATCH($O23,Scoring!$AB$29:$AB$361,0)))) -> 19 | D23: =IF($O23="","",INDEX(Scoring!$Q$29:$Q$361,MATCH($O23,Scoring!$AB$29:$AB$361,0))) -> Priority 2 | E23: =IF($O23="","",INDEX(Scoring!$AJ$29:$AJ$361,MATCH($O23,Scoring!$AB$29:$AB$361,0))) -> High price · lower volume | F23: =IF($O23="","",INDEX(Scoring!$B$29:$B$361,MATCH($O23,Scoring!$AB$29:$AB$361,0))) -> Leuprorelin | G23: =IF($O23="","",INDEX(Scoring!$AG$29:$AG$361,MATCH($O23,Scoring!$AB$29:$AB$361,0))) -> Camcevi | H23: =IF($O23="","",INDEX(Scoring!$C$29:$C$361,MATCH($O23,Scoring!$AB$29:$AB$361,0))) -> Oncology: hormone therapy for advanced prostate cancer | I23: =IF($O23="","",INDEX(Scoring!$I$29:$I$361,MATCH($O23,Scoring!$AB$29:$AB$361,0))) -> Prefilled syringe | J23: =IF($O23="","",INDEX(Scoring!$Z$29:$Z$361,MATCH($O23,Scoring!$AB$29:$AB$361,0))) -> 21 mg pre-filled syringe; 21 mg/0.25 mL pre-filled syringe | K23: =IF($O23="","",IF(INDEX(Scoring!$D$29:$D$361,MATCH($O23,Scoring!$AB$29:$AB$361,0))="",INDEX(Scoring!$AF$29:$AF$361,MATCH($O23,Scoring!$AB$29:$AB$361,0)),INDEX(Scoring!$D$29:$D$361,MATCH($O23,Scoring!$AB$29:$AB$361,0)))) -> 433.94 | L23: =IF($O23="","",INDEX(Scoring!$M$29:$M$361,MATCH($O23,Scoring!$AB$29:$AB$361,0))) -> 111 | M23: =IF($O23="","",INDEX(Scoring!$F$29:$F$361,MATCH($O23,Scoring!$AB$29:$AB$361,0))) -> 2489.4 | N23: =IF($O23="","",INDEX(Scoring!$AI$29:$AI$361,MATCH($O23,Scoring!$AB$29:$AB$361,0))) -> UK | EU/EEA: all 30 countries | O23: =IFERROR(SMALL(Scoring!$AB$29:$AB$361,19),"") -> 1019
A24: =IF($O24="","",INT($O24/1000)) -> 1 | B24: =IF($O24="","",INDEX(Scoring!$A$29:$A$361,MATCH($O24,Scoring!$AB$29:$AB$361,0))) -> Intas | C24: =IF($O24="","",IF(INDEX(Scoring!$P$29:$P$361,MATCH($O24,Scoring!$AB$29:$AB$361,0))="","–",INDEX(Scoring!$P$29:$P$361,MATCH($O24,Scoring!$AB$29:$AB$361,0)))) -> 20 | D24: =IF($O24="","",INDEX(Scoring!$Q$29:$Q$361,MATCH($O24,Scoring!$AB$29:$AB$361,0))) -> Priority 2 | E24: =IF($O24="","",INDEX(Scoring!$AJ$29:$AJ$361,MATCH($O24,Scoring!$AB$29:$AB$361,0))) -> High price · lower volume | F24: =IF($O24="","",INDEX(Scoring!$B$29:$B$361,MATCH($O24,Scoring!$AB$29:$AB$361,0))) -> Ustekinumab | G24: =IF($O24="","",INDEX(Scoring!$AG$29:$AG$361,MATCH($O24,Scoring!$AB$29:$AB$361,0))) -> Imuldosa | H24: =IF($O24="","",INDEX(Scoring!$C$29:$C$361,MATCH($O24,Scoring!$AB$29:$AB$361,0))) -> Immunology: psoriasis, psoriatic arthritis, Crohn's disease, ulcerative colitis | I24: =IF($O24="","",INDEX(Scoring!$I$29:$I$361,MATCH($O24,Scoring!$AB$29:$AB$361,0))) -> Prefilled syringe | J24: =IF($O24="","",INDEX(Scoring!$Z$29:$Z$361,MATCH($O24,Scoring!$AB$29:$AB$361,0))) -> 45 mg/0.5 mL pre-filled syringe | K24: =IF($O24="","",IF(INDEX(Scoring!$D$29:$D$361,MATCH($O24,Scoring!$AB$29:$AB$361,0))="",INDEX(Scoring!$AF$29:$AF$361,MATCH($O24,Scoring!$AB$29:$AB$361,0)),INDEX(Scoring!$D$29:$D$361,MATCH($O24,Scoring!$AB$29:$AB$361,0)))) -> 2838.33 | L24: =IF($O24="","",INDEX(Scoring!$M$29:$M$361,MATCH($O24,Scoring!$AB$29:$AB$361,0))) -> 125 | M24: =IF($O24="","",INDEX(Scoring!$F$29:$F$361,MATCH($O24,Scoring!$AB$29:$AB$361,0))) -> 2485.9 | N24: =IF($O24="","",INDEX(Scoring!$AI$29:$AI$361,MATCH($O24,Scoring!$AB$29:$AB$361,0))) -> UK, UK-NI | EU/EEA: all 30 countries | O24: =IFERROR(SMALL(Scoring!$AB$29:$AB$361,20),"") -> 1020
A25: =IF($O25="","",INT($O25/1000)) -> 1 | B25: =IF($O25="","",INDEX(Scoring!$A$29:$A$361,MATCH($O25,Scoring!$AB$29:$AB$361,0))) -> Intas | C25: =IF($O25="","",IF(INDEX(Scoring!$P$29:$P$361,MATCH($O25,Scoring!$AB$29:$AB$361,0))="","–",INDEX(Scoring!$P$29:$P$361,MATCH($O25,Scoring!$AB$29:$AB$361,0)))) -> 21 | D25: =IF($O25="","",INDEX(Scoring!$Q$29:$Q$361,MATCH($O25,Scoring!$AB$29:$AB$361,0))) -> Priority 2 | E25: =IF($O25="","",INDEX(Scoring!$AJ$29:$AJ$361,MATCH($O25,Scoring!$AB$29:$AB$361,0))) -> High price · lower volume | F25: =IF($O25="","",INDEX(Scoring!$B$29:$B$361,MATCH($O25,Scoring!$AB$29:$AB$361,0))) -> Degarelix | G25: =IF($O25="","",INDEX(Scoring!$AG$29:$AG$361,MATCH($O25,Scoring!$AB$29:$AB$361,0))) -> Degarelix; Degarelix Accord | H25: =IF($O25="","",INDEX(Scoring!$C$29:$C$361,MATCH($O25,Scoring!$AB$29:$AB$361,0))) -> Oncology: hormone therapy for advanced prostate cancer | I25: =IF($O25="","",INDEX(Scoring!$I$29:$I$361,MATCH($O25,Scoring!$AB$29:$AB$361,0))) -> Vial | J25: =IF($O25="","",INDEX(Scoring!$Z$29:$Z$361,MATCH($O25,Scoring!$AB$29:$AB$361,0))) -> 80 mg powder vial | K25: =IF($O25="","",IF(INDEX(Scoring!$D$29:$D$361,MATCH($O25,Scoring!$AB$29:$AB$361,0))="",INDEX(Scoring!$AF$29:$AF$361,MATCH($O25,Scoring!$AB$29:$AB$361,0)),INDEX(Scoring!$D$29:$D$361,MATCH($O25,Scoring!$AB$29:$AB$361,0)))) -> 92.62 | L25: =IF($O25="","",INDEX(Scoring!$M$29:$M$361,MATCH($O25,Scoring!$AB$29:$AB$361,0))) -> 26 | M25: =IF($O25="","",INDEX(Scoring!$F$29:$F$361,MATCH($O25,Scoring!$AB$29:$AB$361,0))) -> 140.9 | N25: =IF($O25="","",INDEX(Scoring!$AI$29:$AI$361,MATCH($O25,Scoring!$AB$29:$AB$361,0))) -> UK | EU/EEA: all 30 countries | O25: =IFERROR(SMALL(Scoring!$AB$29:$AB$361,21),"") -> 1021
A26: =IF($O26="","",INT($O26/1000)) -> 1 | B26: =IF($O26="","",INDEX(Scoring!$A$29:$A$361,MATCH($O26,Scoring!$AB$29:$AB$361,0))) -> Intas | C26: =IF($O26="","",IF(INDEX(Scoring!$P$29:$P$361,MATCH($O26,Scoring!$AB$29:$AB$361,0))="","–",INDEX(Scoring!$P$29:$P$361,MATCH($O26,Scoring!$AB$29:$AB$361,0)))) -> 22 | D26: =IF($O26="","",INDEX(Scoring!$Q$29:$Q$361,MATCH($O26,Scoring!$AB$29:$AB$361,0))) -> Priority 3 | E26: =IF($O26="","",INDEX(Scoring!$AJ$29:$AJ$361,MATCH($O26,Scoring!$AB$29:$AB$361,0))) -> Lower price · lower volume | F26: =IF($O26="","",INDEX(Scoring!$B$29:$B$361,MATCH($O26,Scoring!$AB$29:$AB$361,0))) -> Flucloxacillin | G26: =IF($O26="","",INDEX(Scoring!$AG$29:$AG$361,MATCH($O26,Scoring!$AB$29:$AB$361,0))) -> Floxapen | H26: =IF($O26="","",INDEX(Scoring!$C$29:$C$361,MATCH($O26,Scoring!$AB$29:$AB$361,0))) -> Anti-infective: staphylococcal skin, bone and heart infections | I26: =IF($O26="","",INDEX(Scoring!$I$29:$I$361,MATCH($O26,Scoring!$AB$29:$AB$361,0))) -> Vial | J26: =IF($O26="","",INDEX(Scoring!$Z$29:$Z$361,MATCH($O26,Scoring!$AB$29:$AB$361,0))) -> 500 mg powder vial | K26: =IF($O26="","",IF(INDEX(Scoring!$D$29:$D$361,MATCH($O26,Scoring!$AB$29:$AB$361,0))="",INDEX(Scoring!$AF$29:$AF$361,MATCH($O26,Scoring!$AB$29:$AB$361,0)),INDEX(Scoring!$D$29:$D$361,MATCH($O26,Scoring!$AB$29:$AB$361,0)))) -> 6.07 | L26: =IF($O26="","",INDEX(Scoring!$M$29:$M$361,MATCH($O26,Scoring!$AB$29:$AB$361,0))) -> 116 | M26: =IF($O26="","",INDEX(Scoring!$F$29:$F$361,MATCH($O26,Scoring!$AB$29:$AB$361,0))) -> 6287.6 | N26: =IF($O26="","",INDEX(Scoring!$AI$29:$AI$361,MATCH($O26,Scoring!$AB$29:$AB$361,0))) -> UK-NI | O26: =IFERROR(SMALL(Scoring!$AB$29:$AB$361,22),"") -> 1022
A27: =IF($O27="","",INT($O27/1000)) -> 1 | B27: =IF($O27="","",INDEX(Scoring!$A$29:$A$361,MATCH($O27,Scoring!$AB$29:$AB$361,0))) -> Intas | C27: =IF($O27="","",IF(INDEX(Scoring!$P$29:$P$361,MATCH($O27,Scoring!$AB$29:$AB$361,0))="","–",INDEX(Scoring!$P$29:$P$361,MATCH($O27,Scoring!$AB$29:$AB$361,0)))) -> 23 | D27: =IF($O27="","",INDEX(Scoring!$Q$29:$Q$361,MATCH($O27,Scoring!$AB$29:$AB$361,0))) -> Priority 3 | E27: =IF($O27="","",INDEX(Scoring!$AJ$29:$AJ$361,MATCH($O27,Scoring!$AB$29:$AB$361,0))) -> Lower price · lower volume | F27: =IF($O27="","",INDEX(Scoring!$B$29:$B$361,MATCH($O27,Scoring!$AB$29:$AB$361,0))) -> Progesterone | G27: =IF($O27="","",INDEX(Scoring!$AG$29:$AG$361,MATCH($O27,Scoring!$AB$29:$AB$361,0))) -> Progesterone | H27: =IF($O27="","",INDEX(Scoring!$C$29:$C$361,MATCH($O27,Scoring!$AB$29:$AB$361,0))) -> Women's health: IVF support, absent periods, abnormal uterine bleeding | I27: =IF($O27="","",INDEX(Scoring!$I$29:$I$361,MATCH($O27,Scoring!$AB$29:$AB$361,0))) -> Not stated | J27: =IF($O27="","",INDEX(Scoring!$Z$29:$Z$361,MATCH($O27,Scoring!$AB$29:$AB$361,0))) -> 50 mg/mL (container not stated) | K27: =IF($O27="","",IF(INDEX(Scoring!$D$29:$D$361,MATCH($O27,Scoring!$AB$29:$AB$361,0))="",INDEX(Scoring!$AF$29:$AF$361,MATCH($O27,Scoring!$AB$29:$AB$361,0)),INDEX(Scoring!$D$29:$D$361,MATCH($O27,Scoring!$AB$29:$AB$361,0)))) -> 6.23 | L27: =IF($O27="","",INDEX(Scoring!$M$29:$M$361,MATCH($O27,Scoring!$AB$29:$AB$361,0))) -> 88 | M27: =IF($O27="","",INDEX(Scoring!$F$29:$F$361,MATCH($O27,Scoring!$AB$29:$AB$361,0))) -> 2646.6 | N27: =IF($O27="","",INDEX(Scoring!$AI$29:$AI$361,MATCH($O27,Scoring!$AB$29:$AB$361,0))) -> US | O27: =IFERROR(SMALL(Scoring!$AB$29:$AB$361,23),"") -> 1023
A28: =IF($O28="","",INT($O28/1000)) -> 1 | B28: =IF($O28="","",INDEX(Scoring!$A$29:$A$361,MATCH($O28,Scoring!$AB$29:$AB$361,0))) -> Intas | C28: =IF($O28="","",IF(INDEX(Scoring!$P$29:$P$361,MATCH($O28,Scoring!$AB$29:$AB$361,0))="","–",INDEX(Scoring!$P$29:$P$361,MATCH($O28,Scoring!$AB$29:$AB$361,0)))) -> 24 | D28: =IF($O28="","",INDEX(Scoring!$Q$29:$Q$361,MATCH($O28,Scoring!$AB$29:$AB$361,0))) -> Priority 3 | E28: =IF($O28="","",INDEX(Scoring!$AJ$29:$AJ$361,MATCH($O28,Scoring!$AB$29:$AB$361,0))) -> Lower price · lower volume | F28: =IF($O28="","",INDEX(Scoring!$B$29:$B$361,MATCH($O28,Scoring!$AB$29:$AB$361,0))) -> Colistimethate Sodium | G28: =IF($O28="","",INDEX(Scoring!$AG$29:$AG$361,MATCH($O28,Scoring!$AB$29:$AB$361,0))) -> Colistimethate Sodium; Colistimetato Accord | H28: =IF($O28="","",INDEX(Scoring!$C$29:$C$361,MATCH($O28,Scoring!$AB$29:$AB$361,0))) -> Anti-infective: last-line treatment for drug-resistant Gram-negative infections | I28: =IF($O28="","",INDEX(Scoring!$I$29:$I$361,MATCH($O28,Scoring!$AB$29:$AB$361,0))) -> Vial | J28: =IF($O28="","",INDEX(Scoring!$Z$29:$Z$361,MATCH($O28,Scoring!$AB$29:$AB$361,0))) -> 2 MIU powder vial; 1 MIU powder vial | K28: =IF($O28="","",IF(INDEX(Scoring!$D$29:$D$361,MATCH($O28,Scoring!$AB$29:$AB$361,0))="",INDEX(Scoring!$AF$29:$AF$361,MATCH($O28,Scoring!$AB$29:$AB$361,0)),INDEX(Scoring!$D$29:$D$361,MATCH($O28,Scoring!$AB$29:$AB$361,0)))) -> 9.75 | L28: =IF($O28="","",INDEX(Scoring!$M$29:$M$361,MATCH($O28,Scoring!$AB$29:$AB$361,0))) -> 83 | M28: =IF($O28="","",INDEX(Scoring!$F$29:$F$361,MATCH($O28,Scoring!$AB$29:$AB$361,0))) -> 2033.7 | N28: =IF($O28="","",INDEX(Scoring!$AI$29:$AI$361,MATCH($O28,Scoring!$AB$29:$AB$361,0))) -> UK, UK-NI | EU/EEA (20): France, Netherlands, Belgium, Austria + 16 more | O28: =IFERROR(SMALL(Scoring!$AB$29:$AB$361,24),"") -> 1024
A29: =IF($O29="","",INT($O29/1000)) -> 1 | B29: =IF($O29="","",INDEX(Scoring!$A$29:$A$361,MATCH($O29,Scoring!$AB$29:$AB$361,0))) -> Intas | C29: =IF($O29="","",IF(INDEX(Scoring!$P$29:$P$361,MATCH($O29,Scoring!$AB$29:$AB$361,0))="","–",INDEX(Scoring!$P$29:$P$361,MATCH($O29,Scoring!$AB$29:$AB$361,0)))) -> 25 | D29: =IF($O29="","",INDEX(Scoring!$Q$29:$Q$361,MATCH($O29,Scoring!$AB$29:$AB$361,0))) -> Priority 3 | E29: =IF($O29="","",INDEX(Scoring!$AJ$29:$AJ$361,MATCH($O29,Scoring!$AB$29:$AB$361,0))) -> Lower price · lower volume | F29: =IF($O29="","",INDEX(Scoring!$B$29:$B$361,MATCH($O29,Scoring!$AB$29:$AB$361,0))) -> Naloxone | G29: =IF($O29="","",INDEX(Scoring!$AG$29:$AG$361,MATCH($O29,Scoring!$AB$29:$AB$361,0))) -> Naloxone Hydrochloride; Naloxone | H29: =IF($O29="","",INDEX(Scoring!$C$29:$C$361,MATCH($O29,Scoring!$AB$29:$AB$361,0))) -> Critical care: reversal of opioid overdose | I29: =IF($O29="","",INDEX(Scoring!$I$29:$I$361,MATCH($O29,Scoring!$AB$29:$AB$361,0))) -> Prefilled syringe | J29: =IF($O29="","",INDEX(Scoring!$Z$29:$Z$361,MATCH($O29,Scoring!$AB$29:$AB$361,0))) -> 0.4 mg/mL (container not stated); 1 mg/mL (container not stated); 400 mcg/mL pre-filled syringe | K29: =IF($O29="","",IF(INDEX(Scoring!$D$29:$D$361,MATCH($O29,Scoring!$AB$29:$AB$361,0))="",INDEX(Scoring!$AF$29:$AF$361,MATCH($O29,Scoring!$AB$29:$AB$361,0)),INDEX(Scoring!$D$29:$D$361,MATCH($O29,Scoring!$AB$29:$AB$361,0)))) -> 5.42 | L29: =IF($O29="","",INDEX(Scoring!$M$29:$M$361,MATCH($O29,Scoring!$AB$29:$AB$361,0))) -> 88 | M29: =IF($O29="","",INDEX(Scoring!$F$29:$F$361,MATCH($O29,Scoring!$AB$29:$AB$361,0))) -> 1437.9 | N29: =IF($O29="","",INDEX(Scoring!$AI$29:$AI$361,MATCH($O29,Scoring!$AB$29:$AB$361,0))) -> US, UK, UK-NI | EU/EEA (12): Germany, France, Netherlands, Austria + 8 more | O29: =IFERROR(SMALL(Scoring!$AB$29:$AB$361,25),"") -> 1025
A30: =IF($O30="","",INT($O30/1000)) -> 1 | B30: =IF($O30="","",INDEX(Scoring!$A$29:$A$361,MATCH($O30,Scoring!$AB$29:$AB$361,0))) -> Intas | C30: =IF($O30="","",IF(INDEX(Scoring!$P$29:$P$361,MATCH($O30,Scoring!$AB$29:$AB$361,0))="","–",INDEX(Scoring!$P$29:$P$361,MATCH($O30,Scoring!$AB$29:$AB$361,0)))) -> 26 | D30: =IF($O30="","",INDEX(Scoring!$Q$29:$Q$361,MATCH($O30,Scoring!$AB$29:$AB$361,0))) -> Priority 3 | E30: =IF($O30="","",INDEX(Scoring!$AJ$29:$AJ$361,MATCH($O30,Scoring!$AB$29:$AB$361,0))) -> Lower price · lower volume | F30: =IF($O30="","",INDEX(Scoring!$B$29:$B$361,MATCH($O30,Scoring!$AB$29:$AB$361,0))) -> Hydroxocobalamin | G30: =IF($O30="","",INDEX(Scoring!$AG$29:$AG$361,MATCH($O30,Scoring!$AB$29:$AB$361,0))) -> Hydroxocobalamin Accord Healthcare | H30: =IF($O30="","",INDEX(Scoring!$C$29:$C$361,MATCH($O30,Scoring!$AB$29:$AB$361,0))) -> Haematology: vitamin B12 deficiency, cyanide poisoning | I30: =IF($O30="","",INDEX(Scoring!$I$29:$I$361,MATCH($O30,Scoring!$AB$29:$AB$361,0))) -> Not stated | J30: =IF($O30="","",INDEX(Scoring!$Z$29:$Z$361,MATCH($O30,Scoring!$AB$29:$AB$361,0))) -> 1 mg/mL (container not stated) | K30: =IF($O30="","",IF(INDEX(Scoring!$D$29:$D$361,MATCH($O30,Scoring!$AB$29:$AB$361,0))="",INDEX(Scoring!$AF$29:$AF$361,MATCH($O30,Scoring!$AB$29:$AB$361,0)),INDEX(Scoring!$D$29:$D$361,MATCH($O30,Scoring!$AB$29:$AB$361,0)))) -> 9.83 | L30: =IF($O30="","",INDEX(Scoring!$M$29:$M$361,MATCH($O30,Scoring!$AB$29:$AB$361,0))) -> 22 | M30: =IF($O30="","",INDEX(Scoring!$F$29:$F$361,MATCH($O30,Scoring!$AB$29:$AB$361,0))) -> 315.7 | N30: =IF($O30="","",INDEX(Scoring!$AI$29:$AI$361,MATCH($O30,Scoring!$AB$29:$AB$361,0))) -> UK-NI | O30: =IFERROR(SMALL(Scoring!$AB$29:$AB$361,26),"") -> 1026
A31: =IF($O31="","",INT($O31/1000)) -> 1 | B31: =IF($O31="","",INDEX(Scoring!$A$29:$A$361,MATCH($O31,Scoring!$AB$29:$AB$361,0))) -> Intas | C31: =IF($O31="","",IF(INDEX(Scoring!$P$29:$P$361,MATCH($O31,Scoring!$AB$29:$AB$361,0))="","–",INDEX(Scoring!$P$29:$P$361,MATCH($O31,Scoring!$AB$29:$AB$361,0)))) -> – | D31: =IF($O31="","",INDEX(Scoring!$Q$29:$Q$361,MATCH($O31,Scoring!$AB$29:$AB$361,0))) -> Excluded – price ≤ $5 | E31: =IF($O31="","",INDEX(Scoring!$AJ$29:$AJ$361,MATCH($O31,Scoring!$AB$29:$AB$361,0))) | F31: =IF($O31="","",INDEX(Scoring!$B$29:$B$361,MATCH($O31,Scoring!$AB$29:$AB$361,0))) -> Amoxicillin | G31: =IF($O31="","",INDEX(Scoring!$AG$29:$AG$361,MATCH($O31,Scoring!$AB$29:$AB$361,0))) -> Amoxicillin Accord Healthcare | H31: =IF($O31="","",INDEX(Scoring!$C$29:$C$361,MATCH($O31,Scoring!$AB$29:$AB$361,0))) -> Anti-infective: serious bacterial infections when oral treatment is not possible | I31: =IF($O31="","",INDEX(Scoring!$I$29:$I$361,MATCH($O31,Scoring!$AB$29:$AB$361,0))) -> Not stated | J31: =IF($O31="","",INDEX(Scoring!$Z$29:$Z$361,MATCH($O31,Scoring!$AB$29:$AB$361,0))) -> 500 mg (container not stated) | K31: =IF($O31="","",IF(INDEX(Scoring!$D$29:$D$361,MATCH($O31,Scoring!$AB$29:$AB$361,0))="",INDEX(Scoring!$AF$29:$AF$361,MATCH($O31,Scoring!$AB$29:$AB$361,0)),INDEX(Scoring!$D$29:$D$361,MATCH($O31,Scoring!$AB$29:$AB$361,0)))) -> 1.59 | L31: =IF($O31="","",INDEX(Scoring!$M$29:$M$361,MATCH($O31,Scoring!$AB$29:$AB$361,0))) -> 715 | M31: =IF($O31="","",INDEX(Scoring!$F$29:$F$361,MATCH($O31,Scoring!$AB$29:$AB$361,0))) -> 33794.9 | N31: =IF($O31="","",INDEX(Scoring!$AI$29:$AI$361,MATCH($O31,Scoring!$AB$29:$AB$361,0))) -> UK-NI | EU/EEA (1): Portugal | O31: =IFERROR(SMALL(Scoring!$AB$29:$AB$361,27),"") -> 1901
A32: =IF($O32="","",INT($O32/1000)) -> 1 | B32: =IF($O32="","",INDEX(Scoring!$A$29:$A$361,MATCH($O32,Scoring!$AB$29:$AB$361,0))) -> Intas | C32: =IF($O32="","",IF(INDEX(Scoring!$P$29:$P$361,MATCH($O32,Scoring!$AB$29:$AB$361,0))="","–",INDEX(Scoring!$P$29:$P$361,MATCH($O32,Scoring!$AB$29:$AB$361,0)))) -> – | D32: =IF($O32="","",INDEX(Scoring!$Q$29:$Q$361,MATCH($O32,Scoring!$AB$29:$AB$361,0))) -> Excluded – price ≤ $5 | E32: =IF($O32="","",INDEX(Scoring!$AJ$29:$AJ$361,MATCH($O32,Scoring!$AB$29:$AB$361,0))) | F32: =IF($O32="","",INDEX(Scoring!$B$29:$B$361,MATCH($O32,Scoring!$AB$29:$AB$361,0))) -> Glycopyrrolate | G32: =IF($O32="","",INDEX(Scoring!$AG$29:$AG$361,MATCH($O32,Scoring!$AB$29:$AB$361,0))) -> Glycopyrrolate Accord | H32: =IF($O32="","",INDEX(Scoring!$C$29:$C$361,MATCH($O32,Scoring!$AB$29:$AB$361,0))) -> Anaesthesia: reduces secretions, reversal of muscle relaxants | I32: =IF($O32="","",INDEX(Scoring!$I$29:$I$361,MATCH($O32,Scoring!$AB$29:$AB$361,0))) -> Ampoule | J32: =IF($O32="","",INDEX(Scoring!$Z$29:$Z$361,MATCH($O32,Scoring!$AB$29:$AB$361,0))) -> 0.6 mg/3 mL ampoule | K32: =IF($O32="","",IF(INDEX(Scoring!$D$29:$D$361,MATCH($O32,Scoring!$AB$29:$AB$361,0))="",INDEX(Scoring!$AF$29:$AF$361,MATCH($O32,Scoring!$AB$29:$AB$361,0)),INDEX(Scoring!$D$29:$D$361,MATCH($O32,Scoring!$AB$29:$AB$361,0)))) -> 3 | L32: =IF($O32="","",INDEX(Scoring!$M$29:$M$361,MATCH($O32,Scoring!$AB$29:$AB$361,0))) -> 119 | M32: =IF($O32="","",INDEX(Scoring!$F$29:$F$361,MATCH($O32,Scoring!$AB$29:$AB$361,0))) -> 1332.4 | N32: =IF($O32="","",INDEX(Scoring!$AI$29:$AI$361,MATCH($O32,Scoring!$AB$29:$AB$361,0))) -> Australia, UK-NI | EU/EEA (6): Germany, Austria, Cyprus, Finland, Italy, Sweden | O32: =IFERROR(SMALL(Scoring!$AB$29:$AB$361,28),"") -> 1902
A33: =IF($O33="","",INT($O33/1000)) -> 1 | B33: =IF($O33="","",INDEX(Scoring!$A$29:$A$361,MATCH($O33,Scoring!$AB$29:$AB$361,0))) -> Intas | C33: =IF($O33="","",IF(INDEX(Scoring!$P$29:$P$361,MATCH($O33,Scoring!$AB$29:$AB$361,0))="","–",INDEX(Scoring!$P$29:$P$361,MATCH($O33,Scoring!$AB$29:$AB$361,0)))) -> – | D33: =IF($O33="","",INDEX(Scoring!$Q$29:$Q$361,MATCH($O33,Scoring!$AB$29:$AB$361,0))) -> Excluded – price ≤ $5 | E33: =IF($O33="","",INDEX(Scoring!$AJ$29:$AJ$361,MATCH($O33,Scoring!$AB$29:$AB$361,0))) | F33: =IF($O33="","",INDEX(Scoring!$B$29:$B$361,MATCH($O33,Scoring!$AB$29:$AB$361,0))) -> Lidocaine | G33: =IF($O33="","",INDEX(Scoring!$AG$29:$AG$361,MATCH($O33,Scoring!$AB$29:$AB$361,0))) -> Lidocaine Accord; Lidocaine Intas | H33: =IF($O33="","",INDEX(Scoring!$C$29:$C$361,MATCH($O33,Scoring!$AB$29:$AB$361,0))) -> Anaesthesia: local anaesthetic, ventricular arrhythmias | I33: =IF($O33="","",INDEX(Scoring!$I$29:$I$361,MATCH($O33,Scoring!$AB$29:$AB$361,0))) -> Vial, Ampoule | J33: =IF($O33="","",INDEX(Scoring!$Z$29:$Z$361,MATCH($O33,Scoring!$AB$29:$AB$361,0))) -> 100 mg/5 mL ampoule; 400 mg/20 mL vial; 40 mg/2 mL ampoule; 200 mg/20 mL vial | K33: =IF($O33="","",IF(INDEX(Scoring!$D$29:$D$361,MATCH($O33,Scoring!$AB$29:$AB$361,0))="",INDEX(Scoring!$AF$29:$AF$361,MATCH($O33,Scoring!$AB$29:$AB$361,0)),INDEX(Scoring!$D$29:$D$361,MATCH($O33,Scoring!$AB$29:$AB$361,0)))) -> 1.42 | L33: =IF($O33="","",INDEX(Scoring!$M$29:$M$361,MATCH($O33,Scoring!$AB$29:$AB$361,0))) -> 670 | M33: =IF($O33="","",INDEX(Scoring!$F$29:$F$361,MATCH($O33,Scoring!$AB$29:$AB$361,0))) -> 18611.6 | N33: =IF($O33="","",INDEX(Scoring!$AI$29:$AI$361,MATCH($O33,Scoring!$AB$29:$AB$361,0))) -> Australia, UK-NI | EU/EEA (7): Austria, Cyprus, Estonia, Lithuania + 3 more | O33: =IFERROR(SMALL(Scoring!$AB$29:$AB$361,29),"") -> 1903
A34: =IF($O34="","",INT($O34/1000)) -> 1 | B34: =IF($O34="","",INDEX(Scoring!$A$29:$A$361,MATCH($O34,Scoring!$AB$29:$AB$361,0))) -> Intas | C34: =IF($O34="","",IF(INDEX(Scoring!$P$29:$P$361,MATCH($O34,Scoring!$AB$29:$AB$361,0))="","–",INDEX(Scoring!$P$29:$P$361,MATCH($O34,Scoring!$AB$29:$AB$361,0)))) -> – | D34: =IF($O34="","",INDEX(Scoring!$Q$29:$Q$361,MATCH($O34,Scoring!$AB$29:$AB$361,0))) -> Excluded – price ≤ $5 | E34: =IF($O34="","",INDEX(Scoring!$AJ$29:$AJ$361,MATCH($O34,Scoring!$AB$29:$AB$361,0))) | F34: =IF($O34="","",INDEX(Scoring!$B$29:$B$361,MATCH($O34,Scoring!$AB$29:$AB$361,0))) -> Phenytoin | G34: =IF($O34="","",INDEX(Scoring!$AG$29:$AG$361,MATCH($O34,Scoring!$AB$29:$AB$361,0))) -> Phenytoin Accord | H34: =IF($O34="","",INDEX(Scoring!$C$29:$C$361,MATCH($O34,Scoring!$AB$29:$AB$361,0))) -> Neurology: status epilepticus, seizure prevention | I34: =IF($O34="","",INDEX(Scoring!$I$29:$I$361,MATCH($O34,Scoring!$AB$29:$AB$361,0))) -> Not stated | J34: =IF($O34="","",INDEX(Scoring!$Z$29:$Z$361,MATCH($O34,Scoring!$AB$29:$AB$361,0))) -> 100 mg/2 mL (container not stated) | K34: =IF($O34="","",IF(INDEX(Scoring!$D$29:$D$361,MATCH($O34,Scoring!$AB$29:$AB$361,0))="",INDEX(Scoring!$AF$29:$AF$361,MATCH($O34,Scoring!$AB$29:$AB$361,0)),INDEX(Scoring!$D$29:$D$361,MATCH($O34,Scoring!$AB$29:$AB$361,0)))) -> 4.49 | L34: =IF($O34="","",INDEX(Scoring!$M$29:$M$361,MATCH($O34,Scoring!$AB$29:$AB$361,0))) -> 208 | M34: =IF($O34="","",INDEX(Scoring!$F$29:$F$361,MATCH($O34,Scoring!$AB$29:$AB$361,0))) -> 2009.5 | N34: =IF($O34="","",INDEX(Scoring!$AI$29:$AI$361,MATCH($O34,Scoring!$AB$29:$AB$361,0))) -> UK-NI | EU/EEA (1): Portugal | O34: =IFERROR(SMALL(Scoring!$AB$29:$AB$361,30),"") -> 1904
A35: =IF($O35="","",INT($O35/1000)) -> 2 | B35: =IF($O35="","",INDEX(Scoring!$A$29:$A$361,MATCH($O35,Scoring!$AB$29:$AB$361,0))) -> Aurobindo | C35: =IF($O35="","",IF(INDEX(Scoring!$P$29:$P$361,MATCH($O35,Scoring!$AB$29:$AB$361,0))="","–",INDEX(Scoring!$P$29:$P$361,MATCH($O35,Scoring!$AB$29:$AB$361,0)))) -> 1 | D35: =IF($O35="","",INDEX(Scoring!$Q$29:$Q$361,MATCH($O35,Scoring!$AB$29:$AB$361,0))) -> Priority 1 | E35: =IF($O35="","",INDEX(Scoring!$AJ$29:$AJ$361,MATCH($O35,Scoring!$AB$29:$AB$361,0))) -> High price · high volume | F35: =IF($O35="","",INDEX(Scoring!$B$29:$B$361,MATCH($O35,Scoring!$AB$29:$AB$361,0))) -> Ertapenem | G35: =IF($O35="","",INDEX(Scoring!$AG$29:$AG$361,MATCH($O35,Scoring!$AB$29:$AB$361,0))) -> Ertapenem Sodium; Ertapenem; Etamep (+1 more) | H35: =IF($O35="","",INDEX(Scoring!$C$29:$C$361,MATCH($O35,Scoring!$AB$29:$AB$361,0))) -> Anti-infective: abdominal, skin and urinary infections, pneumonia | I35: =IF($O35="","",INDEX(Scoring!$I$29:$I$361,MATCH($O35,Scoring!$AB$29:$AB$361,0))) -> Vial | J35: =IF($O35="","",INDEX(Scoring!$Z$29:$Z$361,MATCH($O35,Scoring!$AB$29:$AB$361,0))) -> 1 g powder vial; 1 g in 20 mL powder vial | K35: =IF($O35="","",IF(INDEX(Scoring!$D$29:$D$361,MATCH($O35,Scoring!$AB$29:$AB$361,0))="",INDEX(Scoring!$AF$29:$AF$361,MATCH($O35,Scoring!$AB$29:$AB$361,0)),INDEX(Scoring!$D$29:$D$361,MATCH($O35,Scoring!$AB$29:$AB$361,0)))) -> 28.55 | L35: =IF($O35="","",INDEX(Scoring!$M$29:$M$361,MATCH($O35,Scoring!$AB$29:$AB$361,0))) -> 223 | M35: =IF($O35="","",INDEX(Scoring!$F$29:$F$361,MATCH($O35,Scoring!$AB$29:$AB$361,0))) -> 53539.9 | N35: =IF($O35="","",INDEX(Scoring!$AI$29:$AI$361,MATCH($O35,Scoring!$AB$29:$AB$361,0))) -> US, Canada, South Africa, UK-NI | EU/EEA (6): France, Italy, Poland, Portugal, Romania, Spain | O35: =IFERROR(SMALL(Scoring!$AB$29:$AB$361,31),"") -> 2001
A36: =IF($O36="","",INT($O36/1000)) -> 2 | B36: =IF($O36="","",INDEX(Scoring!$A$29:$A$361,MATCH($O36,Scoring!$AB$29:$AB$361,0))) -> Aurobindo | C36: =IF($O36="","",IF(INDEX(Scoring!$P$29:$P$361,MATCH($O36,Scoring!$AB$29:$AB$361,0))="","–",INDEX(Scoring!$P$29:$P$361,MATCH($O36,Scoring!$AB$29:$AB$361,0)))) -> 2 | D36: =IF($O36="","",INDEX(Scoring!$Q$29:$Q$361,MATCH($O36,Scoring!$AB$29:$AB$361,0))) -> Priority 1 | E36: =IF($O36="","",INDEX(Scoring!$AJ$29:$AJ$361,MATCH($O36,Scoring!$AB$29:$AB$361,0))) -> High price · high volume | F36: =IF($O36="","",INDEX(Scoring!$B$29:$B$361,MATCH($O36,Scoring!$AB$29:$AB$361,0))) -> Azacitidine | G36: =IF($O36="","",INDEX(Scoring!$AG$29:$AG$361,MATCH($O36,Scoring!$AB$29:$AB$361,0))) -> Azacitidine; Azacitidin Puren; Azacitidine Eugia | H36: =IF($O36="","",INDEX(Scoring!$C$29:$C$361,MATCH($O36,Scoring!$AB$29:$AB$361,0))) -> Oncology: myelodysplastic syndromes, acute myeloid leukaemia | I36: =IF($O36="","",INDEX(Scoring!$I$29:$I$361,MATCH($O36,Scoring!$AB$29:$AB$361,0))) -> Vial | J36: =IF($O36="","",INDEX(Scoring!$Z$29:$Z$361,MATCH($O36,Scoring!$AB$29:$AB$361,0))) -> 25 mg/mL powder vial; 100 mg powder vial | K36: =IF($O36="","",IF(INDEX(Scoring!$D$29:$D$361,MATCH($O36,Scoring!$AB$29:$AB$361,0))="",INDEX(Scoring!$AF$29:$AF$361,MATCH($O36,Scoring!$AB$29:$AB$361,0)),INDEX(Scoring!$D$29:$D$361,MATCH($O36,Scoring!$AB$29:$AB$361,0)))) -> 256.12 | L36: =IF($O36="","",INDEX(Scoring!$M$29:$M$361,MATCH($O36,Scoring!$AB$29:$AB$361,0))) -> 632 | M36: =IF($O36="","",INDEX(Scoring!$F$29:$F$361,MATCH($O36,Scoring!$AB$29:$AB$361,0))) -> 42181.7 | N36: =IF($O36="","",INDEX(Scoring!$AI$29:$AI$361,MATCH($O36,Scoring!$AB$29:$AB$361,0))) -> UK, Australia, UK-NI | EU/EEA (8): Germany, France, Netherlands, Belgium + 4 more | O36: =IFERROR(SMALL(Scoring!$AB$29:$AB$361,32),"") -> 2002
